<?xml version="1.0" ?>
<robot name="converted_robot">
   <link name="world">
      <inertial>
         <origin xyz="0.0 0.0 0.0" rpy="0.0 0.0 0.0"/>
         <mass value="0.0"/>
         <inertia ixx="0.0" iyy="0.0" izz="0.0" ixy="0" ixz="0" iyz="0"/>
      </inertial>
   </link>
   <link name="rh_forearm">
      <inertial>
         <origin xyz="0.0 0.0 0.09" rpy="0.0 0.0 0.0"/>
         <mass value="3.0"/>
         <inertia ixx="0.0138" iyy="0.0138" izz="0.00744" ixy="0" ixz="0" iyz="0"/>
      </inertial>
      <visual name="forearm_0">
         <origin xyz="2.5023164499727795e-05 0.0006274281832173421 0.006174842104563299" rpy="1.2117713571401414 -1.5707754379285288 0.34175604649153496"/>
         <geometry>
            <mesh filename="converted_forearm_0.stl"/>
         </geometry>
         <material name="white"/>
      </visual>
      <visual name="forearm_1">
         <origin xyz="-8.494680512348949e-07 -0.0008928917187008465 0.10662449729912862" rpy="0.041959956052883496 -0.00047618781260272414 0.01095032983600237"/>
         <geometry>
            <mesh filename="converted_forearm_1.stl"/>
         </geometry>
         <material name="white"/>
      </visual>
      <visual name="forearm_collision">
         <origin xyz="-2.3000312765045747e-08 -2.164897719253595e-08 0.0927456223223767" rpy="0.0 0.0 0.0"/>
         <geometry>
            <mesh filename="converted_forearm_collision.stl"/>
         </geometry>
         <material name="white"/>
      </visual>
   </link>
   <link name="world2rh_forearm_fixed_jointbody">
      <inertial>
         <origin xyz="0.0 0.0 0.0" rpy="0.0 0.0 0.0"/>
         <mass value="0.001"/>
         <inertia ixx="1e-09" iyy="1e-09" izz="1e-09" ixy="0" ixz="0" iyz="0"/>
      </inertial>
   </link>
   <joint type="fixed" name="world2rh_forearm_fixed">
      <parent link="world"/>
      <child link="world2rh_forearm_fixed_jointbody"/>
      <origin xyz="0.0 0.0 0.0" rpy="-1.5707963267948966 0.0 -1.5707963267948966"/>
   </joint>
   <joint type="fixed" name="world2rh_forearm_fixed_offset">
      <parent link="world2rh_forearm_fixed_jointbody"/>
      <child link="rh_forearm"/>
      <origin xyz="-0.0 -0.0 -0.0" rpy="0.0 0.0 0.0"/>
   </joint>
   <link name="rh_wrist">
      <inertial>
         <origin xyz="0.0 0.0 0.029" rpy="1.5707963267948966 0.0 1.5707963267948966"/>
         <mass value="0.1"/>
         <inertia ixx="6.4e-05" iyy="4.38e-05" izz="3.5e-05" ixy="0" ixz="0" iyz="0"/>
      </inertial>
      <visual name="wrist">
         <origin xyz="0.0026493678443454513 2.2619274745282502e-05 0.01606431384985827" rpy="1.5546762010448698 -0.0015692253144186097 1.5706727051126772"/>
         <geometry>
            <mesh filename="converted_wrist.stl"/>
         </geometry>
         <material name="white"/>
      </visual>
   </link>
   <link name="rh_WRJ2_jointbody">
      <inertial>
         <origin xyz="0.0 0.0 0.0" rpy="0.0 0.0 0.0"/>
         <mass value="0.001"/>
         <inertia ixx="1e-09" iyy="1e-09" izz="1e-09" ixy="0" ixz="0" iyz="0"/>
      </inertial>
   </link>
   <joint type="revolute" name="rh_WRJ2">
      <parent link="rh_forearm"/>
      <child link="rh_WRJ2_jointbody"/>
      <origin xyz="0.0 -0.01 0.21301" rpy="0.0 0.0 0.0"/>
      <axis xyz="0.0 1.0 0.0"/>
      <limit lower="-0.523599" upper="0.174533" effort="100" velocity="100"/>
   </joint>
   <joint type="fixed" name="rh_WRJ2_offset">
      <parent link="rh_WRJ2_jointbody"/>
      <child link="rh_wrist"/>
      <origin xyz="-0.0 -0.0 -0.0" rpy="0.0 0.0 0.0"/>
   </joint>
   <link name="rh_palm">
      <inertial>
         <origin xyz="0.0 0.0 0.035" rpy="0.0 0.0 1.5707963267948963"/>
         <mass value="0.3"/>
         <inertia ixx="0.0005287" iyy="0.0003581" izz="0.000191" ixy="0" ixz="0" iyz="0"/>
      </inertial>
      <visual name="palm">
         <origin xyz="0.005374445170477271 -0.0022442906559082794 0.03201294312033412" rpy="0.21004583923561293 0.08313278223257159 1.5503210950325146"/>
         <geometry>
            <mesh filename="converted_palm.stl"/>
         </geometry>
         <material name="white"/>
      </visual>
   </link>
   <link name="rh_WRJ1_jointbody">
      <inertial>
         <origin xyz="0.0 0.0 0.0" rpy="0.0 0.0 0.0"/>
         <mass value="0.001"/>
         <inertia ixx="1e-09" iyy="1e-09" izz="1e-09" ixy="0" ixz="0" iyz="0"/>
      </inertial>
   </link>
   <joint type="revolute" name="rh_WRJ1">
      <parent link="rh_wrist"/>
      <child link="rh_WRJ1_jointbody"/>
      <origin xyz="0.0 0.0 0.034" rpy="0.0 0.0 0.0"/>
      <axis xyz="1.0 0.0 0.0"/>
      <limit lower="-0.698132" upper="0.488692" effort="100" velocity="100"/>
   </joint>
   <joint type="fixed" name="rh_WRJ1_offset">
      <parent link="rh_WRJ1_jointbody"/>
      <child link="rh_palm"/>
      <origin xyz="-0.0 -0.0 -0.0" rpy="0.0 0.0 0.0"/>
   </joint>
   <link name="rh_ffknuckle">
      <inertial>
         <origin xyz="0.0 0.0 0.0" rpy="1.5707963267948966 -1.5707963267948966 0.0"/>
         <mass value="0.008"/>
         <inertia ixx="3.2e-07" iyy="2.6e-07" izz="2.6e-07" ixy="0" ixz="0" iyz="0"/>
      </inertial>
      <visual name="f_knuckle">
         <origin xyz="-8.015943942283821e-06 0.00028383334511582203 0.0003141144870240873" rpy="0.47613902951548026 0.007276744315003247 -0.011288848955677028"/>
         <geometry>
            <mesh filename="converted_f_knuckle.stl"/>
         </geometry>
         <material name="white"/>
      </visual>
   </link>
   <link name="rh_FFJ4_jointbody">
      <inertial>
         <origin xyz="0.0 0.0 0.0" rpy="0.0 0.0 0.0"/>
         <mass value="0.001"/>
         <inertia ixx="1e-09" iyy="1e-09" izz="1e-09" ixy="0" ixz="0" iyz="0"/>
      </inertial>
   </link>
   <joint type="revolute" name="rh_FFJ4">
      <parent link="rh_palm"/>
      <child link="rh_FFJ4_jointbody"/>
      <origin xyz="0.033 0.0 0.095" rpy="0.0 0.0 0.0"/>
      <axis xyz="0.0 -1.0 0.0"/>
      <limit lower="-0.349066" upper="0.349066" effort="100" velocity="100"/>
   </joint>
   <joint type="fixed" name="rh_FFJ4_offset">
      <parent link="rh_FFJ4_jointbody"/>
      <child link="rh_ffknuckle"/>
      <origin xyz="-0.0 -0.0 -0.0" rpy="0.0 0.0 0.0"/>
   </joint>
   <link name="rh_ffproximal">
      <inertial>
         <origin xyz="0.0 0.0 0.0225" rpy="0.0 0.0 1.5707963267948963"/>
         <mass value="0.03"/>
         <inertia ixx="1e-05" iyy="9.8e-06" izz="1.8e-06" ixy="0" ixz="0" iyz="0"/>
      </inertial>
      <visual name="f_proximal">
         <origin xyz="1.2104673000657597e-06 9.76175282387983e-06 0.022880653343431333" rpy="-7.135757573717427e-06 0.01189393423812235 1.5705980355726104"/>
         <geometry>
            <mesh filename="converted_f_proximal.stl"/>
         </geometry>
         <material name="white"/>
      </visual>
   </link>
   <link name="rh_FFJ3_jointbody">
      <inertial>
         <origin xyz="0.0 0.0 0.0" rpy="0.0 0.0 0.0"/>
         <mass value="0.001"/>
         <inertia ixx="1e-09" iyy="1e-09" izz="1e-09" ixy="0" ixz="0" iyz="0"/>
      </inertial>
   </link>
   <joint type="revolute" name="rh_FFJ3">
      <parent link="rh_ffknuckle"/>
      <child link="rh_FFJ3_jointbody"/>
      <origin xyz="0.0 0.0 0.0" rpy="0.0 0.0 0.0"/>
      <axis xyz="1.0 0.0 0.0"/>
      <limit lower="-0.261799" upper="1.5708" effort="100" velocity="100"/>
   </joint>
   <joint type="fixed" name="rh_FFJ3_offset">
      <parent link="rh_FFJ3_jointbody"/>
      <child link="rh_ffproximal"/>
      <origin xyz="-0.0 -0.0 -0.0" rpy="0.0 0.0 0.0"/>
   </joint>
   <link name="rh_ffmiddle">
      <inertial>
         <origin xyz="0.0 0.0 0.0125" rpy="0.0 0.0 1.5707963267948963"/>
         <mass value="0.017"/>
         <inertia ixx="2.7e-06" iyy="2.6e-06" izz="8.7e-07" ixy="0" ixz="0" iyz="0"/>
      </inertial>
      <visual name="f_middle">
         <origin xyz="-2.7197407046965675e-06 -3.219283283025054e-05 0.011511409944870538" rpy="-1.5154077996792914e-05 -0.00025673504362555555 1.5707963267948966"/>
         <geometry>
            <mesh filename="converted_f_middle.stl"/>
         </geometry>
         <material name="white"/>
      </visual>
   </link>
   <link name="rh_FFJ2_jointbody">
      <inertial>
         <origin xyz="0.0 0.0 0.0" rpy="0.0 0.0 0.0"/>
         <mass value="0.001"/>
         <inertia ixx="1e-09" iyy="1e-09" izz="1e-09" ixy="0" ixz="0" iyz="0"/>
      </inertial>
   </link>
   <joint type="revolute" name="rh_FFJ2">
      <parent link="rh_ffproximal"/>
      <child link="rh_FFJ2_jointbody"/>
      <origin xyz="0.0 0.0 0.045" rpy="0.0 0.0 0.0"/>
      <axis xyz="1.0 0.0 0.0"/>
      <limit lower="0.0" upper="1.5708" effort="100" velocity="100"/>
   </joint>
   <joint type="fixed" name="rh_FFJ2_offset">
      <parent link="rh_FFJ2_jointbody"/>
      <child link="rh_ffmiddle"/>
      <origin xyz="-0.0 -0.0 -0.0" rpy="0.0 0.0 0.0"/>
   </joint>
   <link name="rh_ffdistal">
      <inertial>
         <origin xyz="0.0 0.0 0.0130769" rpy="0.0 0.0 1.5707963267948963"/>
         <mass value="0.013"/>
         <inertia ixx="1.28092e-06" iyy="1.12092e-06" izz="5.3e-07" ixy="0" ixz="0" iyz="0"/>
      </inertial>
      <visual name="f_distal_pst">
         <origin xyz="-2.398434946392576e-05 0.00042073257364413626 0.017646475317320408" rpy="1.9593220200619932e-05 0.002689843516656465 1.582276007411751"/>
         <geometry>
            <mesh filename="converted_f_distal_pst.stl"/>
         </geometry>
         <material name="white"/>
      </visual>
      <visual name="f_distal_pst">
         <origin xyz="-2.398434946392576e-05 0.00042073257364413626 0.017646475317320408" rpy="1.9593220200619932e-05 0.002689843516656465 1.582276007411751"/>
         <geometry>
            <mesh filename="converted_f_distal_pst.stl"/>
         </geometry>
         <material name="white"/>
      </visual>
   </link>
   <link name="rh_FFJ1_jointbody">
      <inertial>
         <origin xyz="0.0 0.0 0.0" rpy="0.0 0.0 0.0"/>
         <mass value="0.001"/>
         <inertia ixx="1e-09" iyy="1e-09" izz="1e-09" ixy="0" ixz="0" iyz="0"/>
      </inertial>
   </link>
   <joint type="revolute" name="rh_FFJ1">
      <parent link="rh_ffmiddle"/>
      <child link="rh_FFJ1_jointbody"/>
      <origin xyz="0.0 0.0 0.025" rpy="0.0 0.0 0.0"/>
      <axis xyz="1.0 0.0 0.0"/>
      <limit lower="0.0" upper="1.5708" effort="100" velocity="100"/>
   </joint>
   <joint type="fixed" name="rh_FFJ1_offset">
      <parent link="rh_FFJ1_jointbody"/>
      <child link="rh_ffdistal"/>
      <origin xyz="-0.0 -0.0 -0.0" rpy="0.0 0.0 0.0"/>
   </joint>
   <link name="rh_mfknuckle">
      <inertial>
         <origin xyz="0.0 0.0 0.0" rpy="1.5707963267948966 -1.5707963267948966 0.0"/>
         <mass value="0.008"/>
         <inertia ixx="3.2e-07" iyy="2.6e-07" izz="2.6e-07" ixy="0" ixz="0" iyz="0"/>
      </inertial>
      <visual name="f_knuckle">
         <origin xyz="-8.015943942283821e-06 0.00028383334511582203 0.0003141144870240873" rpy="0.47613902951548026 0.007276744315003247 -0.011288848955677028"/>
         <geometry>
            <mesh filename="converted_f_knuckle.stl"/>
         </geometry>
         <material name="white"/>
      </visual>
   </link>
   <link name="rh_MFJ4_jointbody">
      <inertial>
         <origin xyz="0.0 0.0 0.0" rpy="0.0 0.0 0.0"/>
         <mass value="0.001"/>
         <inertia ixx="1e-09" iyy="1e-09" izz="1e-09" ixy="0" ixz="0" iyz="0"/>
      </inertial>
   </link>
   <joint type="revolute" name="rh_MFJ4">
      <parent link="rh_palm"/>
      <child link="rh_MFJ4_jointbody"/>
      <origin xyz="0.011 0.0 0.099" rpy="0.0 0.0 0.0"/>
      <axis xyz="0.0 -1.0 0.0"/>
      <limit lower="-0.349066" upper="0.349066" effort="100" velocity="100"/>
   </joint>
   <joint type="fixed" name="rh_MFJ4_offset">
      <parent link="rh_MFJ4_jointbody"/>
      <child link="rh_mfknuckle"/>
      <origin xyz="-0.0 -0.0 -0.0" rpy="0.0 0.0 0.0"/>
   </joint>
   <link name="rh_mfproximal">
      <inertial>
         <origin xyz="0.0 0.0 0.0225" rpy="0.0 0.0 1.5707963267948963"/>
         <mass value="0.03"/>
         <inertia ixx="1e-05" iyy="9.8e-06" izz="1.8e-06" ixy="0" ixz="0" iyz="0"/>
      </inertial>
      <visual name="f_proximal">
         <origin xyz="1.2104673000657597e-06 9.76175282387983e-06 0.022880653343431333" rpy="-7.135757573717427e-06 0.01189393423812235 1.5705980355726104"/>
         <geometry>
            <mesh filename="converted_f_proximal.stl"/>
         </geometry>
         <material name="white"/>
      </visual>
   </link>
   <link name="rh_MFJ3_jointbody">
      <inertial>
         <origin xyz="0.0 0.0 0.0" rpy="0.0 0.0 0.0"/>
         <mass value="0.001"/>
         <inertia ixx="1e-09" iyy="1e-09" izz="1e-09" ixy="0" ixz="0" iyz="0"/>
      </inertial>
   </link>
   <joint type="revolute" name="rh_MFJ3">
      <parent link="rh_mfknuckle"/>
      <child link="rh_MFJ3_jointbody"/>
      <origin xyz="0.0 0.0 0.0" rpy="0.0 0.0 0.0"/>
      <axis xyz="1.0 0.0 0.0"/>
      <limit lower="-0.261799" upper="1.5708" effort="100" velocity="100"/>
   </joint>
   <joint type="fixed" name="rh_MFJ3_offset">
      <parent link="rh_MFJ3_jointbody"/>
      <child link="rh_mfproximal"/>
      <origin xyz="-0.0 -0.0 -0.0" rpy="0.0 0.0 0.0"/>
   </joint>
   <link name="rh_mfmiddle">
      <inertial>
         <origin xyz="0.0 0.0 0.0125" rpy="0.0 0.0 1.5707963267948963"/>
         <mass value="0.017"/>
         <inertia ixx="2.7e-06" iyy="2.6e-06" izz="8.7e-07" ixy="0" ixz="0" iyz="0"/>
      </inertial>
      <visual name="f_middle">
         <origin xyz="-2.7197407046965675e-06 -3.219283283025054e-05 0.011511409944870538" rpy="-1.5154077996792914e-05 -0.00025673504362555555 1.5707963267948966"/>
         <geometry>
            <mesh filename="converted_f_middle.stl"/>
         </geometry>
         <material name="white"/>
      </visual>
   </link>
   <link name="rh_MFJ2_jointbody">
      <inertial>
         <origin xyz="0.0 0.0 0.0" rpy="0.0 0.0 0.0"/>
         <mass value="0.001"/>
         <inertia ixx="1e-09" iyy="1e-09" izz="1e-09" ixy="0" ixz="0" iyz="0"/>
      </inertial>
   </link>
   <joint type="revolute" name="rh_MFJ2">
      <parent link="rh_mfproximal"/>
      <child link="rh_MFJ2_jointbody"/>
      <origin xyz="0.0 0.0 0.045" rpy="0.0 0.0 0.0"/>
      <axis xyz="1.0 0.0 0.0"/>
      <limit lower="0.0" upper="1.5708" effort="100" velocity="100"/>
   </joint>
   <joint type="fixed" name="rh_MFJ2_offset">
      <parent link="rh_MFJ2_jointbody"/>
      <child link="rh_mfmiddle"/>
      <origin xyz="-0.0 -0.0 -0.0" rpy="0.0 0.0 0.0"/>
   </joint>
   <link name="rh_mfdistal">
      <inertial>
         <origin xyz="0.0 0.0 0.0130769" rpy="0.0 0.0 1.5707963267948963"/>
         <mass value="0.013"/>
         <inertia ixx="1.28092e-06" iyy="1.12092e-06" izz="5.3e-07" ixy="0" ixz="0" iyz="0"/>
      </inertial>
      <visual name="f_distal_pst">
         <origin xyz="-2.398434946392576e-05 0.00042073257364413626 0.017646475317320408" rpy="1.9593220200619932e-05 0.002689843516656465 1.582276007411751"/>
         <geometry>
            <mesh filename="converted_f_distal_pst.stl"/>
         </geometry>
         <material name="white"/>
      </visual>
      <visual name="f_distal_pst">
         <origin xyz="-2.398434946392576e-05 0.00042073257364413626 0.017646475317320408" rpy="1.9593220200619932e-05 0.002689843516656465 1.582276007411751"/>
         <geometry>
            <mesh filename="converted_f_distal_pst.stl"/>
         </geometry>
         <material name="white"/>
      </visual>
   </link>
   <link name="rh_MFJ1_jointbody">
      <inertial>
         <origin xyz="0.0 0.0 0.0" rpy="0.0 0.0 0.0"/>
         <mass value="0.001"/>
         <inertia ixx="1e-09" iyy="1e-09" izz="1e-09" ixy="0" ixz="0" iyz="0"/>
      </inertial>
   </link>
   <joint type="revolute" name="rh_MFJ1">
      <parent link="rh_mfmiddle"/>
      <child link="rh_MFJ1_jointbody"/>
      <origin xyz="0.0 0.0 0.025" rpy="0.0 0.0 0.0"/>
      <axis xyz="1.0 0.0 0.0"/>
      <limit lower="0.0" upper="1.5708" effort="100" velocity="100"/>
   </joint>
   <joint type="fixed" name="rh_MFJ1_offset">
      <parent link="rh_MFJ1_jointbody"/>
      <child link="rh_mfdistal"/>
      <origin xyz="-0.0 -0.0 -0.0" rpy="0.0 0.0 0.0"/>
   </joint>
   <link name="rh_rfknuckle">
      <inertial>
         <origin xyz="0.0 0.0 0.0" rpy="1.5707963267948966 -1.5707963267948966 0.0"/>
         <mass value="0.008"/>
         <inertia ixx="3.2e-07" iyy="2.6e-07" izz="2.6e-07" ixy="0" ixz="0" iyz="0"/>
      </inertial>
      <visual name="f_knuckle">
         <origin xyz="-8.015943942283821e-06 0.00028383334511582203 0.0003141144870240873" rpy="0.47613902951548026 0.007276744315003247 -0.011288848955677028"/>
         <geometry>
            <mesh filename="converted_f_knuckle.stl"/>
         </geometry>
         <material name="white"/>
      </visual>
   </link>
   <link name="rh_RFJ4_jointbody">
      <inertial>
         <origin xyz="0.0 0.0 0.0" rpy="0.0 0.0 0.0"/>
         <mass value="0.001"/>
         <inertia ixx="1e-09" iyy="1e-09" izz="1e-09" ixy="0" ixz="0" iyz="0"/>
      </inertial>
   </link>
   <joint type="revolute" name="rh_RFJ4">
      <parent link="rh_palm"/>
      <child link="rh_RFJ4_jointbody"/>
      <origin xyz="-0.011 0.0 0.095" rpy="0.0 0.0 0.0"/>
      <axis xyz="0.0 1.0 0.0"/>
      <limit lower="-0.349066" upper="0.349066" effort="100" velocity="100"/>
   </joint>
   <joint type="fixed" name="rh_RFJ4_offset">
      <parent link="rh_RFJ4_jointbody"/>
      <child link="rh_rfknuckle"/>
      <origin xyz="-0.0 -0.0 -0.0" rpy="0.0 0.0 0.0"/>
   </joint>
   <link name="rh_rfproximal">
      <inertial>
         <origin xyz="0.0 0.0 0.0225" rpy="0.0 0.0 1.5707963267948963"/>
         <mass value="0.03"/>
         <inertia ixx="1e-05" iyy="9.8e-06" izz="1.8e-06" ixy="0" ixz="0" iyz="0"/>
      </inertial>
      <visual name="f_proximal">
         <origin xyz="1.2104673000657597e-06 9.76175282387983e-06 0.022880653343431333" rpy="-7.135757573717427e-06 0.01189393423812235 1.5705980355726104"/>
         <geometry>
            <mesh filename="converted_f_proximal.stl"/>
         </geometry>
         <material name="white"/>
      </visual>
   </link>
   <link name="rh_RFJ3_jointbody">
      <inertial>
         <origin xyz="0.0 0.0 0.0" rpy="0.0 0.0 0.0"/>
         <mass value="0.001"/>
         <inertia ixx="1e-09" iyy="1e-09" izz="1e-09" ixy="0" ixz="0" iyz="0"/>
      </inertial>
   </link>
   <joint type="revolute" name="rh_RFJ3">
      <parent link="rh_rfknuckle"/>
      <child link="rh_RFJ3_jointbody"/>
      <origin xyz="0.0 0.0 0.0" rpy="0.0 0.0 0.0"/>
      <axis xyz="1.0 0.0 0.0"/>
      <limit lower="-0.261799" upper="1.5708" effort="100" velocity="100"/>
   </joint>
   <joint type="fixed" name="rh_RFJ3_offset">
      <parent link="rh_RFJ3_jointbody"/>
      <child link="rh_rfproximal"/>
      <origin xyz="-0.0 -0.0 -0.0" rpy="0.0 0.0 0.0"/>
   </joint>
   <link name="rh_rfmiddle">
      <inertial>
         <origin xyz="0.0 0.0 0.0125" rpy="0.0 0.0 1.5707963267948963"/>
         <mass value="0.017"/>
         <inertia ixx="2.7e-06" iyy="2.6e-06" izz="8.7e-07" ixy="0" ixz="0" iyz="0"/>
      </inertial>
      <visual name="f_middle">
         <origin xyz="-2.7197407046965675e-06 -3.219283283025054e-05 0.011511409944870538" rpy="-1.5154077996792914e-05 -0.00025673504362555555 1.5707963267948966"/>
         <geometry>
            <mesh filename="converted_f_middle.stl"/>
         </geometry>
         <material name="white"/>
      </visual>
   </link>
   <link name="rh_RFJ2_jointbody">
      <inertial>
         <origin xyz="0.0 0.0 0.0" rpy="0.0 0.0 0.0"/>
         <mass value="0.001"/>
         <inertia ixx="1e-09" iyy="1e-09" izz="1e-09" ixy="0" ixz="0" iyz="0"/>
      </inertial>
   </link>
   <joint type="revolute" name="rh_RFJ2">
      <parent link="rh_rfproximal"/>
      <child link="rh_RFJ2_jointbody"/>
      <origin xyz="0.0 0.0 0.045" rpy="0.0 0.0 0.0"/>
      <axis xyz="1.0 0.0 0.0"/>
      <limit lower="0.0" upper="1.5708" effort="100" velocity="100"/>
   </joint>
   <joint type="fixed" name="rh_RFJ2_offset">
      <parent link="rh_RFJ2_jointbody"/>
      <child link="rh_rfmiddle"/>
      <origin xyz="-0.0 -0.0 -0.0" rpy="0.0 0.0 0.0"/>
   </joint>
   <link name="rh_rfdistal">
      <inertial>
         <origin xyz="0.0 0.0 0.0130769" rpy="0.0 0.0 1.5707963267948963"/>
         <mass value="0.013"/>
         <inertia ixx="1.28092e-06" iyy="1.12092e-06" izz="5.3e-07" ixy="0" ixz="0" iyz="0"/>
      </inertial>
      <visual name="f_distal_pst">
         <origin xyz="-2.398434946392576e-05 0.00042073257364413626 0.017646475317320408" rpy="1.9593220200619932e-05 0.002689843516656465 1.582276007411751"/>
         <geometry>
            <mesh filename="converted_f_distal_pst.stl"/>
         </geometry>
         <material name="white"/>
      </visual>
      <visual name="f_distal_pst">
         <origin xyz="-2.398434946392576e-05 0.00042073257364413626 0.017646475317320408" rpy="1.9593220200619932e-05 0.002689843516656465 1.582276007411751"/>
         <geometry>
            <mesh filename="converted_f_distal_pst.stl"/>
         </geometry>
         <material name="white"/>
      </visual>
   </link>
   <link name="rh_RFJ1_jointbody">
      <inertial>
         <origin xyz="0.0 0.0 0.0" rpy="0.0 0.0 0.0"/>
         <mass value="0.001"/>
         <inertia ixx="1e-09" iyy="1e-09" izz="1e-09" ixy="0" ixz="0" iyz="0"/>
      </inertial>
   </link>
   <joint type="revolute" name="rh_RFJ1">
      <parent link="rh_rfmiddle"/>
      <child link="rh_RFJ1_jointbody"/>
      <origin xyz="0.0 0.0 0.025" rpy="0.0 0.0 0.0"/>
      <axis xyz="1.0 0.0 0.0"/>
      <limit lower="0.0" upper="1.5708" effort="100" velocity="100"/>
   </joint>
   <joint type="fixed" name="rh_RFJ1_offset">
      <parent link="rh_RFJ1_jointbody"/>
      <child link="rh_rfdistal"/>
      <origin xyz="-0.0 -0.0 -0.0" rpy="0.0 0.0 0.0"/>
   </joint>
   <link name="rh_lfmetacarpal">
      <inertial>
         <origin xyz="0.0 0.0 0.04" rpy="0.0 0.0 1.5707963267948963"/>
         <mass value="0.03"/>
         <inertia ixx="1.638e-05" iyy="1.45e-05" izz="4.272e-06" ixy="0" ixz="0" iyz="0"/>
      </inertial>
      <visual name="lf_metacarpal">
         <origin xyz="0.0024777484207099435 0.0006623357325489679 0.03647977452477985" rpy="-0.23066279297032832 0.03969006943108422 1.5495450809139037"/>
         <geometry>
            <mesh filename="converted_lf_metacarpal.stl"/>
         </geometry>
         <material name="white"/>
      </visual>
   </link>
   <link name="rh_LFJ5_jointbody">
      <inertial>
         <origin xyz="0.0 0.0 0.0" rpy="0.0 0.0 0.0"/>
         <mass value="0.001"/>
         <inertia ixx="1e-09" iyy="1e-09" izz="1e-09" ixy="0" ixz="0" iyz="0"/>
      </inertial>
   </link>
   <joint type="revolute" name="rh_LFJ5">
      <parent link="rh_palm"/>
      <child link="rh_LFJ5_jointbody"/>
      <origin xyz="-0.033 0.0 0.02071" rpy="0.0 0.0 0.0"/>
      <axis xyz="0.5735761643640092 0.0 0.819152234736298"/>
      <limit lower="0.0" upper="0.785398" effort="100" velocity="100"/>
   </joint>
   <joint type="fixed" name="rh_LFJ5_offset">
      <parent link="rh_LFJ5_jointbody"/>
      <child link="rh_lfmetacarpal"/>
      <origin xyz="-0.0 -0.0 -0.0" rpy="0.0 0.0 0.0"/>
   </joint>
   <link name="rh_lfknuckle">
      <inertial>
         <origin xyz="0.0 0.0 0.0" rpy="1.5707963267948966 -1.5707963267948966 0.0"/>
         <mass value="0.008"/>
         <inertia ixx="3.2e-07" iyy="2.6e-07" izz="2.6e-07" ixy="0" ixz="0" iyz="0"/>
      </inertial>
      <visual name="f_knuckle">
         <origin xyz="-8.015943942283821e-06 0.00028383334511582203 0.0003141144870240873" rpy="0.47613902951548026 0.007276744315003247 -0.011288848955677028"/>
         <geometry>
            <mesh filename="converted_f_knuckle.stl"/>
         </geometry>
         <material name="white"/>
      </visual>
   </link>
   <link name="rh_LFJ4_jointbody">
      <inertial>
         <origin xyz="0.0 0.0 0.0" rpy="0.0 0.0 0.0"/>
         <mass value="0.001"/>
         <inertia ixx="1e-09" iyy="1e-09" izz="1e-09" ixy="0" ixz="0" iyz="0"/>
      </inertial>
   </link>
   <joint type="revolute" name="rh_LFJ4">
      <parent link="rh_lfmetacarpal"/>
      <child link="rh_LFJ4_jointbody"/>
      <origin xyz="0.0 0.0 0.06579" rpy="0.0 0.0 0.0"/>
      <axis xyz="0.0 1.0 0.0"/>
      <limit lower="-0.349066" upper="0.349066" effort="100" velocity="100"/>
   </joint>
   <joint type="fixed" name="rh_LFJ4_offset">
      <parent link="rh_LFJ4_jointbody"/>
      <child link="rh_lfknuckle"/>
      <origin xyz="-0.0 -0.0 -0.0" rpy="0.0 0.0 0.0"/>
   </joint>
   <link name="rh_lfproximal">
      <inertial>
         <origin xyz="0.0 0.0 0.0225" rpy="0.0 0.0 1.5707963267948963"/>
         <mass value="0.03"/>
         <inertia ixx="1e-05" iyy="9.8e-06" izz="1.8e-06" ixy="0" ixz="0" iyz="0"/>
      </inertial>
      <visual name="f_proximal">
         <origin xyz="1.2104673000657597e-06 9.76175282387983e-06 0.022880653343431333" rpy="-7.135757573717427e-06 0.01189393423812235 1.5705980355726104"/>
         <geometry>
            <mesh filename="converted_f_proximal.stl"/>
         </geometry>
         <material name="white"/>
      </visual>
   </link>
   <link name="rh_LFJ3_jointbody">
      <inertial>
         <origin xyz="0.0 0.0 0.0" rpy="0.0 0.0 0.0"/>
         <mass value="0.001"/>
         <inertia ixx="1e-09" iyy="1e-09" izz="1e-09" ixy="0" ixz="0" iyz="0"/>
      </inertial>
   </link>
   <joint type="revolute" name="rh_LFJ3">
      <parent link="rh_lfknuckle"/>
      <child link="rh_LFJ3_jointbody"/>
      <origin xyz="0.0 0.0 0.0" rpy="0.0 0.0 0.0"/>
      <axis xyz="1.0 0.0 0.0"/>
      <limit lower="-0.261799" upper="1.5708" effort="100" velocity="100"/>
   </joint>
   <joint type="fixed" name="rh_LFJ3_offset">
      <parent link="rh_LFJ3_jointbody"/>
      <child link="rh_lfproximal"/>
      <origin xyz="-0.0 -0.0 -0.0" rpy="0.0 0.0 0.0"/>
   </joint>
   <link name="rh_lfmiddle">
      <inertial>
         <origin xyz="0.0 0.0 0.0125" rpy="0.0 0.0 1.5707963267948963"/>
         <mass value="0.017"/>
         <inertia ixx="2.7e-06" iyy="2.6e-06" izz="8.7e-07" ixy="0" ixz="0" iyz="0"/>
      </inertial>
      <visual name="f_middle">
         <origin xyz="-2.7197407046965675e-06 -3.219283283025054e-05 0.011511409944870538" rpy="-1.5154077996792914e-05 -0.00025673504362555555 1.5707963267948966"/>
         <geometry>
            <mesh filename="converted_f_middle.stl"/>
         </geometry>
         <material name="white"/>
      </visual>
   </link>
   <link name="rh_LFJ2_jointbody">
      <inertial>
         <origin xyz="0.0 0.0 0.0" rpy="0.0 0.0 0.0"/>
         <mass value="0.001"/>
         <inertia ixx="1e-09" iyy="1e-09" izz="1e-09" ixy="0" ixz="0" iyz="0"/>
      </inertial>
   </link>
   <joint type="revolute" name="rh_LFJ2">
      <parent link="rh_lfproximal"/>
      <child link="rh_LFJ2_jointbody"/>
      <origin xyz="0.0 0.0 0.045" rpy="0.0 0.0 0.0"/>
      <axis xyz="1.0 0.0 0.0"/>
      <limit lower="0.0" upper="1.5708" effort="100" velocity="100"/>
   </joint>
   <joint type="fixed" name="rh_LFJ2_offset">
      <parent link="rh_LFJ2_jointbody"/>
      <child link="rh_lfmiddle"/>
      <origin xyz="-0.0 -0.0 -0.0" rpy="0.0 0.0 0.0"/>
   </joint>
   <link name="rh_lfdistal">
      <inertial>
         <origin xyz="0.0 0.0 0.0130769" rpy="0.0 0.0 1.5707963267948963"/>
         <mass value="0.013"/>
         <inertia ixx="1.28092e-06" iyy="1.12092e-06" izz="5.3e-07" ixy="0" ixz="0" iyz="0"/>
      </inertial>
      <visual name="f_distal_pst">
         <origin xyz="-2.398434946392576e-05 0.00042073257364413626 0.017646475317320408" rpy="1.9593220200619932e-05 0.002689843516656465 1.582276007411751"/>
         <geometry>
            <mesh filename="converted_f_distal_pst.stl"/>
         </geometry>
         <material name="white"/>
      </visual>
      <visual name="f_distal_pst">
         <origin xyz="-2.398434946392576e-05 0.00042073257364413626 0.017646475317320408" rpy="1.9593220200619932e-05 0.002689843516656465 1.582276007411751"/>
         <geometry>
            <mesh filename="converted_f_distal_pst.stl"/>
         </geometry>
         <material name="white"/>
      </visual>
   </link>
   <link name="rh_LFJ1_jointbody">
      <inertial>
         <origin xyz="0.0 0.0 0.0" rpy="0.0 0.0 0.0"/>
         <mass value="0.001"/>
         <inertia ixx="1e-09" iyy="1e-09" izz="1e-09" ixy="0" ixz="0" iyz="0"/>
      </inertial>
   </link>
   <joint type="revolute" name="rh_LFJ1">
      <parent link="rh_lfmiddle"/>
      <child link="rh_LFJ1_jointbody"/>
      <origin xyz="0.0 0.0 0.025" rpy="0.0 0.0 0.0"/>
      <axis xyz="1.0 0.0 0.0"/>
      <limit lower="0.0" upper="1.5708" effort="100" velocity="100"/>
   </joint>
   <joint type="fixed" name="rh_LFJ1_offset">
      <parent link="rh_LFJ1_jointbody"/>
      <child link="rh_lfdistal"/>
      <origin xyz="-0.0 -0.0 -0.0" rpy="0.0 0.0 0.0"/>
   </joint>
   <link name="rh_thbase">
      <inertial>
         <origin xyz="0.0 0.0 0.0" rpy="0.0 0.0 0.0"/>
         <mass value="0.01"/>
         <inertia ixx="1.6e-07" iyy="1.6e-07" izz="1.6e-07" ixy="0" ixz="0" iyz="0"/>
      </inertial>
   </link>
   <link name="rh_THJ5_jointbody">
      <inertial>
         <origin xyz="0.0 0.0 0.0" rpy="0.0 0.0 0.0"/>
         <mass value="0.001"/>
         <inertia ixx="1e-09" iyy="1e-09" izz="1e-09" ixy="0" ixz="0" iyz="0"/>
      </inertial>
   </link>
   <joint type="revolute" name="rh_THJ5">
      <parent link="rh_palm"/>
      <child link="rh_THJ5_jointbody"/>
      <origin xyz="0.034 -0.00858 0.029" rpy="0.0 0.7853970066908715 0.0"/>
      <axis xyz="0.0 0.0 -1.0"/>
      <limit lower="-1.0472" upper="1.0472" effort="100" velocity="100"/>
   </joint>
   <joint type="fixed" name="rh_THJ5_offset">
      <parent link="rh_THJ5_jointbody"/>
      <child link="rh_thbase"/>
      <origin xyz="-0.0 -0.0 -0.0" rpy="0.0 0.0 0.0"/>
   </joint>
   <link name="rh_thproximal">
      <inertial>
         <origin xyz="0.0 0.0 0.019" rpy="0.0 0.0 0.0"/>
         <mass value="0.04"/>
         <inertia ixx="1.36e-05" iyy="1.36e-05" izz="3.13e-06" ixy="0" ixz="0" iyz="0"/>
      </inertial>
      <visual name="th_proximal">
         <origin xyz="-6.378894056540728e-06 -2.6031284627244637e-05 0.016715298411459745" rpy="-4.1868754547536025e-06 0.0010962409823096486 0.38475878236035044"/>
         <geometry>
            <mesh filename="converted_th_proximal.stl"/>
         </geometry>
         <material name="white"/>
      </visual>
   </link>
   <link name="rh_THJ4_jointbody">
      <inertial>
         <origin xyz="0.0 0.0 0.0" rpy="0.0 0.0 0.0"/>
         <mass value="0.001"/>
         <inertia ixx="1e-09" iyy="1e-09" izz="1e-09" ixy="0" ixz="0" iyz="0"/>
      </inertial>
   </link>
   <joint type="revolute" name="rh_THJ4">
      <parent link="rh_thbase"/>
      <child link="rh_THJ4_jointbody"/>
      <origin xyz="0.0 0.0 0.0" rpy="0.0 0.0 0.0"/>
      <axis xyz="1.0 0.0 0.0"/>
      <limit lower="0.0" upper="1.22173" effort="100" velocity="100"/>
   </joint>
   <joint type="fixed" name="rh_THJ4_offset">
      <parent link="rh_THJ4_jointbody"/>
      <child link="rh_thproximal"/>
      <origin xyz="-0.0 -0.0 -0.0" rpy="0.0 0.0 0.0"/>
   </joint>
   <link name="rh_thhub">
      <inertial>
         <origin xyz="0.0 0.0 0.0" rpy="0.0 0.0 0.0"/>
         <mass value="0.005"/>
         <inertia ixx="1e-06" iyy="1e-06" izz="3e-07" ixy="0" ixz="0" iyz="0"/>
      </inertial>
   </link>
   <link name="rh_THJ3_jointbody">
      <inertial>
         <origin xyz="0.0 0.0 0.0" rpy="0.0 0.0 0.0"/>
         <mass value="0.001"/>
         <inertia ixx="1e-09" iyy="1e-09" izz="1e-09" ixy="0" ixz="0" iyz="0"/>
      </inertial>
   </link>
   <joint type="revolute" name="rh_THJ3">
      <parent link="rh_thproximal"/>
      <child link="rh_THJ3_jointbody"/>
      <origin xyz="0.0 0.0 0.038" rpy="0.0 0.0 0.0"/>
      <axis xyz="1.0 0.0 0.0"/>
      <limit lower="-0.20944" upper="0.20944" effort="100" velocity="100"/>
   </joint>
   <joint type="fixed" name="rh_THJ3_offset">
      <parent link="rh_THJ3_jointbody"/>
      <child link="rh_thhub"/>
      <origin xyz="-0.0 -0.0 -0.0" rpy="0.0 0.0 0.0"/>
   </joint>
   <link name="rh_thmiddle">
      <inertial>
         <origin xyz="0.0 0.0 0.016" rpy="0.0 0.0 0.0"/>
         <mass value="0.02"/>
         <inertia ixx="5.1e-06" iyy="5.1e-06" izz="1.21e-06" ixy="0" ixz="0" iyz="0"/>
      </inertial>
      <visual name="th_middle">
         <origin xyz="7.479629857400793e-05 -4.506977852869377e-05 0.015348398308984388" rpy="0.0 -0.0009035488116577728 0.0"/>
         <geometry>
            <mesh filename="converted_th_middle.stl"/>
         </geometry>
         <material name="white"/>
      </visual>
   </link>
   <link name="rh_THJ2_jointbody">
      <inertial>
         <origin xyz="0.0 0.0 0.0" rpy="0.0 0.0 0.0"/>
         <mass value="0.001"/>
         <inertia ixx="1e-09" iyy="1e-09" izz="1e-09" ixy="0" ixz="0" iyz="0"/>
      </inertial>
   </link>
   <joint type="revolute" name="rh_THJ2">
      <parent link="rh_thhub"/>
      <child link="rh_THJ2_jointbody"/>
      <origin xyz="0.0 0.0 0.0" rpy="0.0 0.0 0.0"/>
      <axis xyz="0.0 -1.0 0.0"/>
      <limit lower="-0.698132" upper="0.698132" effort="100" velocity="100"/>
   </joint>
   <joint type="fixed" name="rh_THJ2_offset">
      <parent link="rh_THJ2_jointbody"/>
      <child link="rh_thmiddle"/>
      <origin xyz="-0.0 -0.0 -0.0" rpy="0.0 0.0 0.0"/>
   </joint>
   <link name="rh_thdistal">
      <inertial>
         <origin xyz="0.0 0.0 0.0145588" rpy="0.0 0.0 1.5707963267948963"/>
         <mass value="0.017"/>
         <inertia ixx="2.37794e-06" iyy="2.27794e-06" izz="1e-06" ixy="0" ixz="0" iyz="0"/>
      </inertial>
      <visual name="th_distal_pst">
         <origin xyz="-8.254509753145168e-07 0.000802518759472585 0.019553373143358997" rpy="-0.00010731819470755077 0.003173495876248822 1.5706693697416252"/>
         <geometry>
            <mesh filename="converted_th_distal_pst.stl"/>
         </geometry>
         <material name="white"/>
      </visual>
      <visual name="th_distal_pst">
         <origin xyz="-8.254509753145168e-07 0.000802518759472585 0.019553373143358997" rpy="-0.00010731819470755077 0.003173495876248822 1.5706693697416252"/>
         <geometry>
            <mesh filename="converted_th_distal_pst.stl"/>
         </geometry>
         <material name="white"/>
      </visual>
   </link>
   <link name="rh_THJ1_jointbody">
      <inertial>
         <origin xyz="0.0 0.0 0.0" rpy="0.0 0.0 0.0"/>
         <mass value="0.001"/>
         <inertia ixx="1e-09" iyy="1e-09" izz="1e-09" ixy="0" ixz="0" iyz="0"/>
      </inertial>
   </link>
   <joint type="revolute" name="rh_THJ1">
      <parent link="rh_thmiddle"/>
      <child link="rh_THJ1_jointbody"/>
      <origin xyz="0.0 0.0 0.032" rpy="0.0 0.0 -1.5707963267948957"/>
      <axis xyz="1.0 0.0 0.0"/>
      <limit lower="-0.261799" upper="1.5708" effort="100" velocity="100"/>
   </joint>
   <joint type="fixed" name="rh_THJ1_offset">
      <parent link="rh_THJ1_jointbody"/>
      <child link="rh_thdistal"/>
      <origin xyz="-0.0 -0.0 -0.0" rpy="0.0 0.0 0.0"/>
   </joint>
   <material name="white">
      <color rgba="1 1 1 1"/>
   </material>
</robot>
